<?xml version="1.0" ?>
<robot name="Sunny-ROS" xmlns:xacro="http://www.ros.org/wiki/xacro">

<xacro:include filename="$(find Sunny-ROS_description)/urdf/materials.xacro" />
<xacro:include filename="$(find Sunny-ROS_description)/urdf/Sunny-ROS.trans" />
<xacro:include filename="$(find Sunny-ROS_description)/urdf/Sunny-ROS.gazebo" />
<link name="base_link">
  <inertial>
    <origin rpy="0 0 0" xyz="-0.0004339332018342215 -0.08649194463184395 0.04993656985806863"/>
    <mass value="0.014036811439882403"/>
    <inertia ixx="2.5e-05" ixy="-0.0" ixz="0.0" iyy="4e-06" iyz="0.0" izz="2.9e-05"/>
  </inertial>
  <visual>
    <origin rpy="0 0 0" xyz="0 0 0"/>
    <geometry>
      <mesh filename="package://Sunny-ROS_description/meshes/base_link.stl" scale="0.001 0.001 0.001"/>
    </geometry>
    <material name="silver"/>
  </visual>
  <collision>
    <origin rpy="0 0 0" xyz="0 0 0"/>
    <geometry>
      <mesh filename="package://Sunny-ROS_description/meshes/base_link.stl" scale="0.001 0.001 0.001"/>
    </geometry>
  </collision>
</link>

<link name="murallaCuerpo_IZQ_v12_1">
  <inertial>
    <origin rpy="0 0 0" xyz="0.016792719511193033 0.04999964721827828 0.026864832536508433"/>
    <mass value="0.0306780316819893"/>
    <inertia ixx="5.8e-05" ixy="0.0" ixz="0.0" iyy="1.8e-05" iyz="0.0" izz="4.6e-05"/>
  </inertial>
  <visual>
    <origin rpy="0 0 0" xyz="-0.029566 0.077327 -0.050687"/>
    <geometry>
      <mesh filename="package://Sunny-ROS_description/meshes/murallaCuerpo_IZQ_v12_1.stl" scale="0.001 0.001 0.001"/>
    </geometry>
    <material name="silver"/>
  </visual>
  <collision>
    <origin rpy="0 0 0" xyz="-0.029566 0.077327 -0.050687"/>
    <geometry>
      <mesh filename="package://Sunny-ROS_description/meshes/murallaCuerpo_IZQ_v12_1.stl" scale="0.001 0.001 0.001"/>
    </geometry>
  </collision>
</link>

<link name="murallaCuerpo_IZQ_1">
  <inertial>
    <origin rpy="0 0 0" xyz="-0.016792585914862653 0.049999647218278466 0.026864832536508475"/>
    <mass value="0.030678031681989244"/>
    <inertia ixx="5.8e-05" ixy="-0.0" ixz="-0.0" iyy="1.8e-05" iyz="0.0" izz="4.6e-05"/>
  </inertial>
  <visual>
    <origin rpy="0 0 0" xyz="0.030434 0.077327 -0.050687"/>
    <geometry>
      <mesh filename="package://Sunny-ROS_description/meshes/murallaCuerpo_IZQ_1.stl" scale="0.001 0.001 0.001"/>
    </geometry>
    <material name="silver"/>
  </visual>
  <collision>
    <origin rpy="0 0 0" xyz="0.030434 0.077327 -0.050687"/>
    <geometry>
      <mesh filename="package://Sunny-ROS_description/meshes/murallaCuerpo_IZQ_1.stl" scale="0.001 0.001 0.001"/>
    </geometry>
  </collision>
</link>

<link name="centroCuerpo_I_1_v9_1">
  <inertial>
    <origin rpy="0 0 0" xyz="0.030000066798165186 0.017780991021617246 -0.0007504301419316919"/>
    <mass value="0.012234171984182826"/>
    <inertia ixx="1.7e-05" ixy="0.0" ixz="0.0" iyy="4e-06" iyz="0.0" izz="2.2e-05"/>
  </inertial>
  <visual>
    <origin rpy="0 0 0" xyz="0.030434 -0.022673 -0.050687"/>
    <geometry>
      <mesh filename="package://Sunny-ROS_description/meshes/centroCuerpo_I_1_v9_1.stl" scale="0.001 0.001 0.001"/>
    </geometry>
    <material name="silver"/>
  </visual>
  <collision>
    <origin rpy="0 0 0" xyz="0.030434 -0.022673 -0.050687"/>
    <geometry>
      <mesh filename="package://Sunny-ROS_description/meshes/centroCuerpo_I_1_v9_1.stl" scale="0.001 0.001 0.001"/>
    </geometry>
  </collision>
</link>

<link name="soporteElectronica_v23_1">
  <inertial>
    <origin rpy="0 0 0" xyz="-0.027255986331712084 -0.014703295421819673 0.01002904369592196"/>
    <mass value="0.020413899246339153"/>
    <inertia ixx="1.4e-05" ixy="-0.0" ixz="0.0" iyy="6e-06" iyz="0.0" izz="1.8e-05"/>
  </inertial>
  <visual>
    <origin rpy="0 0 0" xyz="-0.026822 0.007977 -0.050687"/>
    <geometry>
      <mesh filename="package://Sunny-ROS_description/meshes/soporteElectronica_v23_1.stl" scale="0.001 0.001 0.001"/>
    </geometry>
    <material name="silver"/>
  </visual>
  <collision>
    <origin rpy="0 0 0" xyz="-0.026822 0.007977 -0.050687"/>
    <geometry>
      <mesh filename="package://Sunny-ROS_description/meshes/soporteElectronica_v23_1.stl" scale="0.001 0.001 0.001"/>
    </geometry>
  </collision>
</link>

<link name="MPU_6050_v1_1">
  <inertial>
    <origin rpy="0 0 0" xyz="0.008041740794268034 0.005747207187706698 0.0009291384477591591"/>
    <mass value="0.0005436167057377742"/>
    <inertia ixx="0.0" ixy="-0.0" ixz="-0.0" iyy="0.0" iyz="0.0" izz="0.0"/>
  </inertial>
  <visual>
    <origin rpy="0 0 0" xyz="0.008434 -0.012773 -0.063687"/>
    <geometry>
      <mesh filename="package://Sunny-ROS_description/meshes/MPU_6050_v1_1.stl" scale="0.001 0.001 0.001"/>
    </geometry>
    <material name="silver"/>
  </visual>
  <collision>
    <origin rpy="0 0 0" xyz="0.008434 -0.012773 -0.063687"/>
    <geometry>
      <mesh filename="package://Sunny-ROS_description/meshes/MPU_6050_v1_1.stl" scale="0.001 0.001 0.001"/>
    </geometry>
  </collision>
</link>

<link name="YAAJ_DCDC_StepDown_LM2596_cp_v1_2">
  <inertial>
    <origin rpy="0 0 0" xyz="-0.008374400051936634 -0.013548901850229849 0.0045778982075330155"/>
    <mass value="0.03642581195735508"/>
    <inertia ixx="6e-06" ixy="-0.0" ixz="0.0" iyy="1e-06" iyz="-0.0" izz="7e-06"/>
  </inertial>
  <visual>
    <origin rpy="0 0 0" xyz="-0.021166 0.012127 -0.063687"/>
    <geometry>
      <mesh filename="package://Sunny-ROS_description/meshes/YAAJ_DCDC_StepDown_LM2596_cp_v1_2.stl" scale="0.001 0.001 0.001"/>
    </geometry>
    <material name="silver"/>
  </visual>
  <collision>
    <origin rpy="0 0 0" xyz="-0.021166 0.012127 -0.063687"/>
    <geometry>
      <mesh filename="package://Sunny-ROS_description/meshes/YAAJ_DCDC_StepDown_LM2596_cp_v1_2.stl" scale="0.001 0.001 0.001"/>
    </geometry>
  </collision>
</link>

<link name="YAAJ_DCDC_StepDown_LM2596_cp_v1_1">
  <inertial>
    <origin rpy="0 0 0" xyz="-0.008374400051936456 -0.01354890185022986 0.0045778982075330155"/>
    <mass value="0.03642581195735508"/>
    <inertia ixx="6e-06" ixy="-0.0" ixz="0.0" iyy="1e-06" iyz="-0.0" izz="7e-06"/>
  </inertial>
  <visual>
    <origin rpy="0 0 0" xyz="0.005534 0.012027 -0.063687"/>
    <geometry>
      <mesh filename="package://Sunny-ROS_description/meshes/YAAJ_DCDC_StepDown_LM2596_cp_v1_1.stl" scale="0.001 0.001 0.001"/>
    </geometry>
    <material name="silver"/>
  </visual>
  <collision>
    <origin rpy="0 0 0" xyz="0.005534 0.012027 -0.063687"/>
    <geometry>
      <mesh filename="package://Sunny-ROS_description/meshes/YAAJ_DCDC_StepDown_LM2596_cp_v1_1.stl" scale="0.001 0.001 0.001"/>
    </geometry>
  </collision>
</link>

<link name="Medidor_de_Bateria_2">
  <inertial>
    <origin rpy="0 0 0" xyz="0.004093454727043963 -3.527817203780037e-07 -0.010000430141930527"/>
    <mass value="0.04057589974657529"/>
    <inertia ixx="5e-06" ixy="0.0" ixz="0.0" iyy="1e-06" iyz="0.0" izz="4e-06"/>
  </inertial>
  <visual>
    <origin rpy="0 0 0" xyz="0.057434 0.027327 -0.077937"/>
    <geometry>
      <mesh filename="package://Sunny-ROS_description/meshes/Medidor_de_Bateria_2.stl" scale="0.001 0.001 0.001"/>
    </geometry>
    <material name="silver"/>
  </visual>
  <collision>
    <origin rpy="0 0 0" xyz="0.057434 0.027327 -0.077937"/>
    <geometry>
      <mesh filename="package://Sunny-ROS_description/meshes/Medidor_de_Bateria_2.stl" scale="0.001 0.001 0.001"/>
    </geometry>
  </collision>
</link>

<link name="Medidor_de_Bateria_1">
  <inertial>
    <origin rpy="0 0 0" xyz="-0.004093321130713895 -3.5278172089148185e-07 -0.010000430141931485"/>
    <mass value="0.04057589974657529"/>
    <inertia ixx="5e-06" ixy="-0.0" ixz="-0.0" iyy="1e-06" iyz="0.0" izz="4e-06"/>
  </inertial>
  <visual>
    <origin rpy="0 0 0" xyz="-0.056566 0.027327 -0.077687"/>
    <geometry>
      <mesh filename="package://Sunny-ROS_description/meshes/Medidor_de_Bateria_1.stl" scale="0.001 0.001 0.001"/>
    </geometry>
    <material name="silver"/>
  </visual>
  <collision>
    <origin rpy="0 0 0" xyz="-0.056566 0.027327 -0.077687"/>
    <geometry>
      <mesh filename="package://Sunny-ROS_description/meshes/Medidor_de_Bateria_1.stl" scale="0.001 0.001 0.001"/>
    </geometry>
  </collision>
</link>

<link name="Interruptor_v1_2">
  <inertial>
    <origin rpy="0 0 0" xyz="0.002500733206746285 0.000126179488698714 -0.003500430141931035"/>
    <mass value="0.007983708679622867"/>
    <inertia ixx="0.0" ixy="0.0" ixz="0.0" iyy="0.0" iyz="0.0" izz="0.0"/>
  </inertial>
  <visual>
    <origin rpy="0 0 0" xyz="0.057434 0.027327 -0.097687"/>
    <geometry>
      <mesh filename="package://Sunny-ROS_description/meshes/Interruptor_v1_2.stl" scale="0.001 0.001 0.001"/>
    </geometry>
    <material name="silver"/>
  </visual>
  <collision>
    <origin rpy="0 0 0" xyz="0.057434 0.027327 -0.097687"/>
    <geometry>
      <mesh filename="package://Sunny-ROS_description/meshes/Interruptor_v1_2.stl" scale="0.001 0.001 0.001"/>
    </geometry>
  </collision>
</link>

<link name="Interruptor_v1_1">
  <inertial>
    <origin rpy="0 0 0" xyz="-0.002500599610415044 0.00012617948869828727 -0.0035004301419310213"/>
    <mass value="0.007983708679622867"/>
    <inertia ixx="0.0" ixy="-0.0" ixz="0.0" iyy="0.0" iyz="0.0" izz="0.0"/>
  </inertial>
  <visual>
    <origin rpy="0 0 0" xyz="-0.056566 0.027327 -0.097687"/>
    <geometry>
      <mesh filename="package://Sunny-ROS_description/meshes/Interruptor_v1_1.stl" scale="0.001 0.001 0.001"/>
    </geometry>
    <material name="silver"/>
  </visual>
  <collision>
    <origin rpy="0 0 0" xyz="-0.056566 0.027327 -0.097687"/>
    <geometry>
      <mesh filename="package://Sunny-ROS_description/meshes/Interruptor_v1_1.stl" scale="0.001 0.001 0.001"/>
    </geometry>
  </collision>
</link>

<link name="femaleThruHoleUSB_v1_2">
  <inertial>
    <origin rpy="0 0 0" xyz="-0.009003191009538544 -4.229734727294321e-07 -0.0031860721954535265"/>
    <mass value="0.0007273784143122722"/>
    <inertia ixx="0.0" ixy="-0.0" ixz="-0.0" iyy="0.0" iyz="0.0" izz="0.0"/>
  </inertial>
  <visual>
    <origin rpy="0 0 0" xyz="-0.056566 0.027327 -0.087087"/>
    <geometry>
      <mesh filename="package://Sunny-ROS_description/meshes/femaleThruHoleUSB_v1_2.stl" scale="0.001 0.001 0.001"/>
    </geometry>
    <material name="silver"/>
  </visual>
  <collision>
    <origin rpy="0 0 0" xyz="-0.056566 0.027327 -0.087087"/>
    <geometry>
      <mesh filename="package://Sunny-ROS_description/meshes/femaleThruHoleUSB_v1_2.stl" scale="0.001 0.001 0.001"/>
    </geometry>
  </collision>
</link>

<link name="femaleThruHoleUSB_v1_1">
  <inertial>
    <origin rpy="0 0 0" xyz="0.009003324605869688 -2.825899684845423e-07 -0.0031860721954535265"/>
    <mass value="0.0007273784143122722"/>
    <inertia ixx="0.0" ixy="-0.0" ixz="0.0" iyy="0.0" iyz="-0.0" izz="0.0"/>
  </inertial>
  <visual>
    <origin rpy="0 0 0" xyz="0.057434 0.027327 -0.087087"/>
    <geometry>
      <mesh filename="package://Sunny-ROS_description/meshes/femaleThruHoleUSB_v1_1.stl" scale="0.001 0.001 0.001"/>
    </geometry>
    <material name="silver"/>
  </visual>
  <collision>
    <origin rpy="0 0 0" xyz="0.057434 0.027327 -0.087087"/>
    <geometry>
      <mesh filename="package://Sunny-ROS_description/meshes/femaleThruHoleUSB_v1_1.stl" scale="0.001 0.001 0.001"/>
    </geometry>
  </collision>
</link>

<link name="placa_PCA9685_v1_1">
  <inertial>
    <origin rpy="0 0 0" xyz="0.00888347248096121 -0.026435957523158776 0.0015338386200790116"/>
    <mass value="0.007987541133360362"/>
    <inertia ixx="2e-06" ixy="-0.0" ixz="-0.0" iyy="0.0" iyz="-0.0" izz="3e-06"/>
  </inertial>
  <visual>
    <origin rpy="0 0 0" xyz="0.009834 -0.000623 -0.080687"/>
    <geometry>
      <mesh filename="package://Sunny-ROS_description/meshes/placa_PCA9685_v1_1.stl" scale="0.001 0.001 0.001"/>
    </geometry>
    <material name="silver"/>
  </visual>
  <collision>
    <origin rpy="0 0 0" xyz="0.009834 -0.000623 -0.080687"/>
    <geometry>
      <mesh filename="package://Sunny-ROS_description/meshes/placa_PCA9685_v1_1.stl" scale="0.001 0.001 0.001"/>
    </geometry>
  </collision>
</link>

<link name="motor25KG_v1_3">
  <inertial>
    <origin rpy="0 0 0" xyz="0.005000066798519935 0.0036830135144517995 -0.021727057205523162"/>
    <mass value="0.15217530449100722"/>
    <inertia ixx="4.1e-05" ixy="0.0" ixz="-0.0" iyy="2.7e-05" iyz="-2e-06" izz="2.4e-05"/>
  </inertial>
  <visual>
    <origin rpy="0 0 0" xyz="0.050434 0.082327 -0.101687"/>
    <geometry>
      <mesh filename="package://Sunny-ROS_description/meshes/motor25KG_v1_3.stl" scale="0.001 0.001 0.001"/>
    </geometry>
    <material name="silver"/>
  </visual>
  <collision>
    <origin rpy="0 0 0" xyz="0.050434 0.082327 -0.101687"/>
    <geometry>
      <mesh filename="package://Sunny-ROS_description/meshes/motor25KG_v1_3.stl" scale="0.001 0.001 0.001"/>
    </geometry>
  </collision>
</link>

<link name="motor25KG_v1_4">
  <inertial>
    <origin rpy="0 0 0" xyz="0.005000066798519685 0.0036830135144516607 -0.02172705720552312"/>
    <mass value="0.15217530449100722"/>
    <inertia ixx="4.1e-05" ixy="0.0" ixz="-0.0" iyy="2.7e-05" iyz="-2e-06" izz="2.4e-05"/>
  </inertial>
  <visual>
    <origin rpy="0 0 0" xyz="-0.039566 0.082327 -0.101687"/>
    <geometry>
      <mesh filename="package://Sunny-ROS_description/meshes/motor25KG_v1_4.stl" scale="0.001 0.001 0.001"/>
    </geometry>
    <material name="silver"/>
  </visual>
  <collision>
    <origin rpy="0 0 0" xyz="-0.039566 0.082327 -0.101687"/>
    <geometry>
      <mesh filename="package://Sunny-ROS_description/meshes/motor25KG_v1_4.stl" scale="0.001 0.001 0.001"/>
    </geometry>
  </collision>
</link>

<link name="motor25KG_v1_2">
  <inertial>
    <origin rpy="0 0 0" xyz="0.005000066797811328 -0.003683719077893142 -0.021727057205523412"/>
    <mass value="0.15217530449100722"/>
    <inertia ixx="4.1e-05" ixy="0.0" ixz="0.0" iyy="2.7e-05" iyz="2e-06" izz="2.4e-05"/>
  </inertial>
  <visual>
    <origin rpy="0 0 0" xyz="0.050434 -0.027673 -0.101687"/>
    <geometry>
      <mesh filename="package://Sunny-ROS_description/meshes/motor25KG_v1_2.stl" scale="0.001 0.001 0.001"/>
    </geometry>
    <material name="silver"/>
  </visual>
  <collision>
    <origin rpy="0 0 0" xyz="0.050434 -0.027673 -0.101687"/>
    <geometry>
      <mesh filename="package://Sunny-ROS_description/meshes/motor25KG_v1_2.stl" scale="0.001 0.001 0.001"/>
    </geometry>
  </collision>
</link>

<link name="motor25KG_v1_1">
  <inertial>
    <origin rpy="0 0 0" xyz="0.005000066797811002 -0.0036837190778933396 -0.02172705720552344"/>
    <mass value="0.15217530449100722"/>
    <inertia ixx="4.1e-05" ixy="0.0" ixz="0.0" iyy="2.7e-05" iyz="2e-06" izz="2.4e-05"/>
  </inertial>
  <visual>
    <origin rpy="0 0 0" xyz="-0.039566 -0.027673 -0.101687"/>
    <geometry>
      <mesh filename="package://Sunny-ROS_description/meshes/motor25KG_v1_1.stl" scale="0.001 0.001 0.001"/>
    </geometry>
    <material name="silver"/>
  </visual>
  <collision>
    <origin rpy="0 0 0" xyz="-0.039566 -0.027673 -0.101687"/>
    <geometry>
      <mesh filename="package://Sunny-ROS_description/meshes/motor25KG_v1_1.stl" scale="0.001 0.001 0.001"/>
    </geometry>
  </collision>
</link>

<link name="tornilloMotor_2_v1_3">
  <inertial>
    <origin rpy="0 0 0" xyz="6.679808238485574e-08 0.00011428132280934256 -0.005172681251141495"/>
    <mass value="0.006775855380436026"/>
    <inertia ixx="0.0" ixy="0.0" ixz="0.0" iyy="0.0" iyz="-0.0" izz="0.0"/>
  </inertial>
  <visual>
    <origin rpy="0 0 0" xyz="0.045434 0.099077 -0.087187"/>
    <geometry>
      <mesh filename="package://Sunny-ROS_description/meshes/tornilloMotor_2_v1_3.stl" scale="0.001 0.001 0.001"/>
    </geometry>
    <material name="silver"/>
  </visual>
  <collision>
    <origin rpy="0 0 0" xyz="0.045434 0.099077 -0.087187"/>
    <geometry>
      <mesh filename="package://Sunny-ROS_description/meshes/tornilloMotor_2_v1_3.stl" scale="0.001 0.001 0.001"/>
    </geometry>
  </collision>
</link>

<link name="tornilloMotor_2_v1_4">
  <inertial>
    <origin rpy="0 0 0" xyz="6.679808218362782e-08 0.00011428132280917602 -0.005172681251141564"/>
    <mass value="0.006775855380436026"/>
    <inertia ixx="0.0" ixy="0.0" ixz="0.0" iyy="0.0" iyz="-0.0" izz="0.0"/>
  </inertial>
  <visual>
    <origin rpy="0 0 0" xyz="-0.044566 0.099077 -0.087187"/>
    <geometry>
      <mesh filename="package://Sunny-ROS_description/meshes/tornilloMotor_2_v1_4.stl" scale="0.001 0.001 0.001"/>
    </geometry>
    <material name="silver"/>
  </visual>
  <collision>
    <origin rpy="0 0 0" xyz="-0.044566 0.099077 -0.087187"/>
    <geometry>
      <mesh filename="package://Sunny-ROS_description/meshes/tornilloMotor_2_v1_4.stl" scale="0.001 0.001 0.001"/>
    </geometry>
  </collision>
</link>

<link name="tornilloMotor_2_v1_1">
  <inertial>
    <origin rpy="0 0 0" xyz="6.679824782890309e-08 -0.00011498688625091041 -0.005172681251141786"/>
    <mass value="0.006775855380436026"/>
    <inertia ixx="0.0" ixy="0.0" ixz="-0.0" iyy="0.0" iyz="0.0" izz="0.0"/>
  </inertial>
  <visual>
    <origin rpy="0 0 0" xyz="-0.044566 -0.044423 -0.087187"/>
    <geometry>
      <mesh filename="package://Sunny-ROS_description/meshes/tornilloMotor_2_v1_1.stl" scale="0.001 0.001 0.001"/>
    </geometry>
    <material name="silver"/>
  </visual>
  <collision>
    <origin rpy="0 0 0" xyz="-0.044566 -0.044423 -0.087187"/>
    <geometry>
      <mesh filename="package://Sunny-ROS_description/meshes/tornilloMotor_2_v1_1.stl" scale="0.001 0.001 0.001"/>
    </geometry>
  </collision>
</link>

<link name="tornilloMotor_2_v1_2">
  <inertial>
    <origin rpy="0 0 0" xyz="6.679824813421442e-08 -0.00011498688625068143 -0.00517268125114187"/>
    <mass value="0.006775855380436026"/>
    <inertia ixx="0.0" ixy="0.0" ixz="-0.0" iyy="0.0" iyz="0.0" izz="0.0"/>
  </inertial>
  <visual>
    <origin rpy="0 0 0" xyz="0.045434 -0.044423 -0.087187"/>
    <geometry>
      <mesh filename="package://Sunny-ROS_description/meshes/tornilloMotor_2_v1_2.stl" scale="0.001 0.001 0.001"/>
    </geometry>
    <material name="silver"/>
  </visual>
  <collision>
    <origin rpy="0 0 0" xyz="0.045434 -0.044423 -0.087187"/>
    <geometry>
      <mesh filename="package://Sunny-ROS_description/meshes/tornilloMotor_2_v1_2.stl" scale="0.001 0.001 0.001"/>
    </geometry>
  </collision>
</link>

<link name="capsulaMotor_2_v3__1__1">
  <inertial>
    <origin rpy="0 0 0" xyz="-0.0022200342481256477 -0.0013375030051153147 -0.010672880916095542"/>
    <mass value="0.005522722888116606"/>
    <inertia ixx="1e-06" ixy="0.0" ixz="0.0" iyy="1e-06" iyz="0.0" izz="0.0"/>
  </inertial>
  <visual>
    <origin rpy="0 0 0" xyz="0.045434 0.100977 -0.087187"/>
    <geometry>
      <mesh filename="package://Sunny-ROS_description/meshes/capsulaMotor_2_v3__1__1.stl" scale="0.001 0.001 0.001"/>
    </geometry>
    <material name="silver"/>
  </visual>
  <collision>
    <origin rpy="0 0 0" xyz="0.045434 0.100977 -0.087187"/>
    <geometry>
      <mesh filename="package://Sunny-ROS_description/meshes/capsulaMotor_2_v3__1__1.stl" scale="0.001 0.001 0.001"/>
    </geometry>
  </collision>
</link>

<link name="capsulaMotor_2_v3__1__2">
  <inertial>
    <origin rpy="0 0 0" xyz="0.002220167844454869 0.0013367974416737885 -0.01067288091609582"/>
    <mass value="0.005522722888116606"/>
    <inertia ixx="1e-06" ixy="0.0" ixz="-0.0" iyy="1e-06" iyz="-0.0" izz="0.0"/>
  </inertial>
  <visual>
    <origin rpy="0 0 0" xyz="-0.044566 -0.046323 -0.087187"/>
    <geometry>
      <mesh filename="package://Sunny-ROS_description/meshes/capsulaMotor_2_v3__1__2.stl" scale="0.001 0.001 0.001"/>
    </geometry>
    <material name="silver"/>
  </visual>
  <collision>
    <origin rpy="0 0 0" xyz="-0.044566 -0.046323 -0.087187"/>
    <geometry>
      <mesh filename="package://Sunny-ROS_description/meshes/capsulaMotor_2_v3__1__2.stl" scale="0.001 0.001 0.001"/>
    </geometry>
  </collision>
</link>

<link name="capsulaMotor_2_v3_1">
  <inertial>
    <origin rpy="0 0 0" xyz="0.002220166179510534 -0.001337508079961261 -0.01067292367396698"/>
    <mass value="0.005522728174922822"/>
    <inertia ixx="1e-06" ixy="-0.0" ixz="-0.0" iyy="1e-06" iyz="0.0" izz="0.0"/>
  </inertial>
  <visual>
    <origin rpy="0 0 0" xyz="-0.044566 0.100977 -0.087187"/>
    <geometry>
      <mesh filename="package://Sunny-ROS_description/meshes/capsulaMotor_2_v3_1.stl" scale="0.001 0.001 0.001"/>
    </geometry>
    <material name="silver"/>
  </visual>
  <collision>
    <origin rpy="0 0 0" xyz="-0.044566 0.100977 -0.087187"/>
    <geometry>
      <mesh filename="package://Sunny-ROS_description/meshes/capsulaMotor_2_v3_1.stl" scale="0.001 0.001 0.001"/>
    </geometry>
  </collision>
</link>

<link name="capsulaMotor_2_v3_2">
  <inertial>
    <origin rpy="0 0 0" xyz="-0.002220032583181132 0.0013368025165197903 -0.010672923673967341"/>
    <mass value="0.005522728174922822"/>
    <inertia ixx="1e-06" ixy="-0.0" ixz="0.0" iyy="1e-06" iyz="-0.0" izz="0.0"/>
  </inertial>
  <visual>
    <origin rpy="0 0 0" xyz="0.045434 -0.046323 -0.087187"/>
    <geometry>
      <mesh filename="package://Sunny-ROS_description/meshes/capsulaMotor_2_v3_2.stl" scale="0.001 0.001 0.001"/>
    </geometry>
    <material name="silver"/>
  </visual>
  <collision>
    <origin rpy="0 0 0" xyz="0.045434 -0.046323 -0.087187"/>
    <geometry>
      <mesh filename="package://Sunny-ROS_description/meshes/capsulaMotor_2_v3_2.stl" scale="0.001 0.001 0.001"/>
    </geometry>
  </collision>
</link>

<link name="motor25KG_v1__1__1">
  <inertial>
    <origin rpy="0 0 0" xyz="-0.0036832994980070255 -0.021726979845320238 -0.005000430142282963"/>
    <mass value="0.15217530449100722"/>
    <inertia ixx="2.7e-05" ixy="2e-06" ixz="0.0" iyy="2.4e-05" iyz="0.0" izz="4.1e-05"/>
  </inertial>
  <visual>
    <origin rpy="0 0 0" xyz="-0.056566 0.101477 -0.092187"/>
    <geometry>
      <mesh filename="package://Sunny-ROS_description/meshes/motor25KG_v1__1__1.stl" scale="0.001 0.001 0.001"/>
    </geometry>
    <material name="silver"/>
  </visual>
  <collision>
    <origin rpy="0 0 0" xyz="-0.056566 0.101477 -0.092187"/>
    <geometry>
      <mesh filename="package://Sunny-ROS_description/meshes/motor25KG_v1__1__1.stl" scale="0.001 0.001 0.001"/>
    </geometry>
  </collision>
</link>

<link name="motor25KG_v1__1__2">
  <inertial>
    <origin rpy="0 0 0" xyz="-0.0036832994980076084 -0.027273725718132427 0.004999569858425222"/>
    <mass value="0.15217530449100722"/>
    <inertia ixx="2.7e-05" ixy="-2e-06" ixz="-0.0" iyy="2.4e-05" iyz="0.0" izz="4.1e-05"/>
  </inertial>
  <visual>
    <origin rpy="0 0 0" xyz="-0.056566 0.101477 -0.062187"/>
    <geometry>
      <mesh filename="package://Sunny-ROS_description/meshes/motor25KG_v1__1__2.stl" scale="0.001 0.001 0.001"/>
    </geometry>
    <material name="silver"/>
  </visual>
  <collision>
    <origin rpy="0 0 0" xyz="-0.056566 0.101477 -0.062187"/>
    <geometry>
      <mesh filename="package://Sunny-ROS_description/meshes/motor25KG_v1__1__2.stl" scale="0.001 0.001 0.001"/>
    </geometry>
  </collision>
</link>

<link name="motor25KG_v1__1__3">
  <inertial>
    <origin rpy="0 0 0" xyz="-0.0036832994980069284 0.027273020154690276 -0.00500043014228338"/>
    <mass value="0.15217530449100722"/>
    <inertia ixx="2.7e-05" ixy="2e-06" ixz="0.0" iyy="2.4e-05" iyz="0.0" izz="4.1e-05"/>
  </inertial>
  <visual>
    <origin rpy="0 0 0" xyz="-0.056566 -0.046823 -0.092187"/>
    <geometry>
      <mesh filename="package://Sunny-ROS_description/meshes/motor25KG_v1__1__3.stl" scale="0.001 0.001 0.001"/>
    </geometry>
    <material name="silver"/>
  </visual>
  <collision>
    <origin rpy="0 0 0" xyz="-0.056566 -0.046823 -0.092187"/>
    <geometry>
      <mesh filename="package://Sunny-ROS_description/meshes/motor25KG_v1__1__3.stl" scale="0.001 0.001 0.001"/>
    </geometry>
  </collision>
</link>

<link name="motor25KG_v1__1__4">
  <inertial>
    <origin rpy="0 0 0" xyz="-0.0036832994980075945 0.02172627428187853 -0.005000430141575127"/>
    <mass value="0.15217530449100722"/>
    <inertia ixx="2.7e-05" ixy="-2e-06" ixz="-0.0" iyy="2.4e-05" iyz="0.0" izz="4.1e-05"/>
  </inertial>
  <visual>
    <origin rpy="0 0 0" xyz="-0.056566 -0.046823 -0.072187"/>
    <geometry>
      <mesh filename="package://Sunny-ROS_description/meshes/motor25KG_v1__1__4.stl" scale="0.001 0.001 0.001"/>
    </geometry>
    <material name="silver"/>
  </visual>
  <collision>
    <origin rpy="0 0 0" xyz="-0.056566 -0.046823 -0.072187"/>
    <geometry>
      <mesh filename="package://Sunny-ROS_description/meshes/motor25KG_v1__1__4.stl" scale="0.001 0.001 0.001"/>
    </geometry>
  </collision>
</link>

<link name="motor25KG_v1__1__5">
  <inertial>
    <origin rpy="0 0 0" xyz="0.003683433094337142 -0.021726979845320113 -0.005000430141574766"/>
    <mass value="0.15217530449100722"/>
    <inertia ixx="2.7e-05" ixy="-2e-06" ixz="0.0" iyy="2.4e-05" iyz="-0.0" izz="4.1e-05"/>
  </inertial>
  <visual>
    <origin rpy="0 0 0" xyz="0.057434 0.101477 -0.092187"/>
    <geometry>
      <mesh filename="package://Sunny-ROS_description/meshes/motor25KG_v1__1__5.stl" scale="0.001 0.001 0.001"/>
    </geometry>
    <material name="silver"/>
  </visual>
  <collision>
    <origin rpy="0 0 0" xyz="0.057434 0.101477 -0.092187"/>
    <geometry>
      <mesh filename="package://Sunny-ROS_description/meshes/motor25KG_v1__1__5.stl" scale="0.001 0.001 0.001"/>
    </geometry>
  </collision>
</link>

<link name="motor25KG_v1__1__6">
  <inertial>
    <origin rpy="0 0 0" xyz="0.0036834330943366633 -0.02727372571813226 -0.005000430142282811"/>
    <mass value="0.15217530449100722"/>
    <inertia ixx="2.7e-05" ixy="2e-06" ixz="-0.0" iyy="2.4e-05" iyz="-0.0" izz="4.1e-05"/>
  </inertial>
  <visual>
    <origin rpy="0 0 0" xyz="0.057434 0.101477 -0.072187"/>
    <geometry>
      <mesh filename="package://Sunny-ROS_description/meshes/motor25KG_v1__1__6.stl" scale="0.001 0.001 0.001"/>
    </geometry>
    <material name="silver"/>
  </visual>
  <collision>
    <origin rpy="0 0 0" xyz="0.057434 0.101477 -0.072187"/>
    <geometry>
      <mesh filename="package://Sunny-ROS_description/meshes/motor25KG_v1__1__6.stl" scale="0.001 0.001 0.001"/>
    </geometry>
  </collision>
</link>

<link name="motor25KG_v1__1__7">
  <inertial>
    <origin rpy="0 0 0" xyz="0.0036834330943373017 0.027273020154690485 0.004999569858424702"/>
    <mass value="0.15217530449100722"/>
    <inertia ixx="2.7e-05" ixy="-2e-06" ixz="0.0" iyy="2.4e-05" iyz="-0.0" izz="4.1e-05"/>
  </inertial>
  <visual>
    <origin rpy="0 0 0" xyz="0.057434 -0.046823 -0.082187"/>
    <geometry>
      <mesh filename="package://Sunny-ROS_description/meshes/motor25KG_v1__1__7.stl" scale="0.001 0.001 0.001"/>
    </geometry>
    <material name="silver"/>
  </visual>
  <collision>
    <origin rpy="0 0 0" xyz="0.057434 -0.046823 -0.082187"/>
    <geometry>
      <mesh filename="package://Sunny-ROS_description/meshes/motor25KG_v1__1__7.stl" scale="0.001 0.001 0.001"/>
    </geometry>
  </collision>
</link>

<link name="motor25KG_v1__1__8">
  <inertial>
    <origin rpy="0 0 0" xyz="0.003683433094336802 0.021726274281878684 0.004999569857716678"/>
    <mass value="0.15217530449100722"/>
    <inertia ixx="2.7e-05" ixy="2e-06" ixz="-0.0" iyy="2.4e-05" iyz="-0.0" izz="4.1e-05"/>
  </inertial>
  <visual>
    <origin rpy="0 0 0" xyz="0.057434 -0.046823 -0.062187"/>
    <geometry>
      <mesh filename="package://Sunny-ROS_description/meshes/motor25KG_v1__1__8.stl" scale="0.001 0.001 0.001"/>
    </geometry>
    <material name="silver"/>
  </visual>
  <collision>
    <origin rpy="0 0 0" xyz="0.057434 -0.046823 -0.062187"/>
    <geometry>
      <mesh filename="package://Sunny-ROS_description/meshes/motor25KG_v1__1__8.stl" scale="0.001 0.001 0.001"/>
    </geometry>
  </collision>
</link>

<link name="capsulaMotor_1_v3_2">
  <inertial>
    <origin rpy="0 0 0" xyz="0.010016411633526706 -0.000605497398625629 -0.01560146944421173"/>
    <mass value="0.006165639163592312"/>
    <inertia ixx="1e-06" ixy="0.0" ixz="0.0" iyy="1e-06" iyz="0.0" izz="0.0"/>
  </inertial>
  <visual>
    <origin rpy="0 0 0" xyz="0.057434 -0.095823 -0.092187"/>
    <geometry>
      <mesh filename="package://Sunny-ROS_description/meshes/capsulaMotor_1_v3_2.stl" scale="0.001 0.001 0.001"/>
    </geometry>
    <material name="silver"/>
  </visual>
  <collision>
    <origin rpy="0 0 0" xyz="0.057434 -0.095823 -0.092187"/>
    <geometry>
      <mesh filename="package://Sunny-ROS_description/meshes/capsulaMotor_1_v3_2.stl" scale="0.001 0.001 0.001"/>
    </geometry>
  </collision>
</link>

<link name="capsulaMotor_1_v3__1__2">
  <inertial>
    <origin rpy="0 0 0" xyz="0.01001642592083056 0.0006048023087244225 -0.015601548023692097"/>
    <mass value="0.0061655983277369274"/>
    <inertia ixx="1e-06" ixy="-0.0" ixz="0.0" iyy="1e-06" iyz="-0.0" izz="0.0"/>
  </inertial>
  <visual>
    <origin rpy="0 0 0" xyz="0.057434 0.150477 -0.092187"/>
    <geometry>
      <mesh filename="package://Sunny-ROS_description/meshes/capsulaMotor_1_v3__1__2.stl" scale="0.001 0.001 0.001"/>
    </geometry>
    <material name="silver"/>
  </visual>
  <collision>
    <origin rpy="0 0 0" xyz="0.057434 0.150477 -0.092187"/>
    <geometry>
      <mesh filename="package://Sunny-ROS_description/meshes/capsulaMotor_1_v3__1__2.stl" scale="0.001 0.001 0.001"/>
    </geometry>
  </collision>
</link>

<link name="capsulaMotor_1_v3_1">
  <inertial>
    <origin rpy="0 0 0" xyz="-0.010016278037197353 0.000604791835183971 -0.015601469444211105"/>
    <mass value="0.006165639163592312"/>
    <inertia ixx="1e-06" ixy="0.0" ixz="-0.0" iyy="1e-06" iyz="-0.0" izz="0.0"/>
  </inertial>
  <visual>
    <origin rpy="0 0 0" xyz="-0.056566 0.150477 -0.092187"/>
    <geometry>
      <mesh filename="package://Sunny-ROS_description/meshes/capsulaMotor_1_v3_1.stl" scale="0.001 0.001 0.001"/>
    </geometry>
    <material name="silver"/>
  </visual>
  <collision>
    <origin rpy="0 0 0" xyz="-0.056566 0.150477 -0.092187"/>
    <geometry>
      <mesh filename="package://Sunny-ROS_description/meshes/capsulaMotor_1_v3_1.stl" scale="0.001 0.001 0.001"/>
    </geometry>
  </collision>
</link>

<link name="capsulaMotor_1_v3__1__1">
  <inertial>
    <origin rpy="0 0 0" xyz="-0.01001629232450122 -0.00060550787216615 -0.015601548023692527"/>
    <mass value="0.0061655983277369274"/>
    <inertia ixx="1e-06" ixy="-0.0" ixz="-0.0" iyy="1e-06" iyz="0.0" izz="0.0"/>
  </inertial>
  <visual>
    <origin rpy="0 0 0" xyz="-0.056566 -0.095823 -0.092187"/>
    <geometry>
      <mesh filename="package://Sunny-ROS_description/meshes/capsulaMotor_1_v3__1__1.stl" scale="0.001 0.001 0.001"/>
    </geometry>
    <material name="silver"/>
  </visual>
  <collision>
    <origin rpy="0 0 0" xyz="-0.056566 -0.095823 -0.092187"/>
    <geometry>
      <mesh filename="package://Sunny-ROS_description/meshes/capsulaMotor_1_v3__1__1.stl" scale="0.001 0.001 0.001"/>
    </geometry>
  </collision>
</link>

<link name="piernaSuperior_v3_2">
  <inertial>
    <origin rpy="0 0 0" xyz="0.009171497580547722 0.04423212482144401 -4.30141933044359e-07"/>
    <mass value="0.03636159738658226"/>
    <inertia ixx="4.1e-05" ixy="-1e-06" ixz="-0.0" iyy="2e-06" iyz="-0.0" izz="4.1e-05"/>
  </inertial>
  <visual>
    <origin rpy="0 0 0" xyz="-0.073316 0.115977 -0.087187"/>
    <geometry>
      <mesh filename="package://Sunny-ROS_description/meshes/piernaSuperior_v3_2.stl" scale="0.001 0.001 0.001"/>
    </geometry>
    <material name="silver"/>
  </visual>
  <collision>
    <origin rpy="0 0 0" xyz="-0.073316 0.115977 -0.087187"/>
    <geometry>
      <mesh filename="package://Sunny-ROS_description/meshes/piernaSuperior_v3_2.stl" scale="0.001 0.001 0.001"/>
    </geometry>
  </collision>
</link>

<link name="piernaSuperior_v3_1">
  <inertial>
    <origin rpy="0 0 0" xyz="0.009171497580548096 0.044232124821454444 -4.301419335162038e-07"/>
    <mass value="0.03636159738658226"/>
    <inertia ixx="4.1e-05" ixy="-1e-06" ixz="-0.0" iyy="2e-06" iyz="-0.0" izz="4.1e-05"/>
  </inertial>
  <visual>
    <origin rpy="0 0 0" xyz="-0.073316 -0.081323 -0.087187"/>
    <geometry>
      <mesh filename="package://Sunny-ROS_description/meshes/piernaSuperior_v3_1.stl" scale="0.001 0.001 0.001"/>
    </geometry>
    <material name="silver"/>
  </visual>
  <collision>
    <origin rpy="0 0 0" xyz="-0.073316 -0.081323 -0.087187"/>
    <geometry>
      <mesh filename="package://Sunny-ROS_description/meshes/piernaSuperior_v3_1.stl" scale="0.001 0.001 0.001"/>
    </geometry>
  </collision>
</link>

<link name="piernaSuperior_v3_4">
  <inertial>
    <origin rpy="0 0 0" xyz="-0.00917136398421775 0.044232124821444035 -4.3014192513401994e-07"/>
    <mass value="0.03636159738658226"/>
    <inertia ixx="4.1e-05" ixy="1e-06" ixz="-0.0" iyy="2e-06" iyz="0.0" izz="4.1e-05"/>
  </inertial>
  <visual>
    <origin rpy="0 0 0" xyz="0.074184 0.115977 -0.087187"/>
    <geometry>
      <mesh filename="package://Sunny-ROS_description/meshes/piernaSuperior_v3_4.stl" scale="0.001 0.001 0.001"/>
    </geometry>
    <material name="silver"/>
  </visual>
  <collision>
    <origin rpy="0 0 0" xyz="0.074184 0.115977 -0.087187"/>
    <geometry>
      <mesh filename="package://Sunny-ROS_description/meshes/piernaSuperior_v3_4.stl" scale="0.001 0.001 0.001"/>
    </geometry>
  </collision>
</link>

<link name="piernaSuperior_v3_3">
  <inertial>
    <origin rpy="0 0 0" xyz="-0.009171363984217501 0.044232124821454694 -4.301419256336203e-07"/>
    <mass value="0.03636159738658226"/>
    <inertia ixx="4.1e-05" ixy="1e-06" ixz="-0.0" iyy="2e-06" iyz="0.0" izz="4.1e-05"/>
  </inertial>
  <visual>
    <origin rpy="0 0 0" xyz="0.074184 -0.081323 -0.087187"/>
    <geometry>
      <mesh filename="package://Sunny-ROS_description/meshes/piernaSuperior_v3_3.stl" scale="0.001 0.001 0.001"/>
    </geometry>
    <material name="silver"/>
  </visual>
  <collision>
    <origin rpy="0 0 0" xyz="0.074184 -0.081323 -0.087187"/>
    <geometry>
      <mesh filename="package://Sunny-ROS_description/meshes/piernaSuperior_v3_3.stl" scale="0.001 0.001 0.001"/>
    </geometry>
  </collision>
</link>

<link name="Rodamiento_684Z_v2_4">
  <inertial>
    <origin rpy="0 0 0" xyz="6.679823923855244e-08 -0.0018003527817260223 -4.3014192899204495e-07"/>
    <mass value="0.0014793330260135641"/>
    <inertia ixx="0.0" ixy="0.0" ixz="-0.0" iyy="0.0" iyz="0.0" izz="0.0"/>
  </inertial>
  <visual>
    <origin rpy="0 0 0" xyz="-0.044566 0.149977 -0.087187"/>
    <geometry>
      <mesh filename="package://Sunny-ROS_description/meshes/Rodamiento_684Z_v2_4.stl" scale="0.001 0.001 0.001"/>
    </geometry>
    <material name="silver"/>
  </visual>
  <collision>
    <origin rpy="0 0 0" xyz="-0.044566 0.149977 -0.087187"/>
    <geometry>
      <mesh filename="package://Sunny-ROS_description/meshes/Rodamiento_684Z_v2_4.stl" scale="0.001 0.001 0.001"/>
    </geometry>
  </collision>
</link>

<link name="Rodamiento_684Z_v2_2">
  <inertial>
    <origin rpy="0 0 0" xyz="6.679823948141372e-08 -0.001800352781725384 -4.3014192889490044e-07"/>
    <mass value="0.0014793330260135641"/>
    <inertia ixx="0.0" ixy="0.0" ixz="-0.0" iyy="0.0" iyz="-0.0" izz="0.0"/>
  </inertial>
  <visual>
    <origin rpy="0 0 0" xyz="0.045434 0.149977 -0.087187"/>
    <geometry>
      <mesh filename="package://Sunny-ROS_description/meshes/Rodamiento_684Z_v2_2.stl" scale="0.001 0.001 0.001"/>
    </geometry>
    <material name="silver"/>
  </visual>
  <collision>
    <origin rpy="0 0 0" xyz="0.045434 0.149977 -0.087187"/>
    <geometry>
      <mesh filename="package://Sunny-ROS_description/meshes/Rodamiento_684Z_v2_2.stl" scale="0.001 0.001 0.001"/>
    </geometry>
  </collision>
</link>

<link name="Rodamiento_684Z_v2_1">
  <inertial>
    <origin rpy="0 0 0" xyz="6.679823934957474e-08 0.0017996472182842532 -4.3014192943613416e-07"/>
    <mass value="0.0014793330260135641"/>
    <inertia ixx="0.0" ixy="0.0" ixz="0.0" iyy="0.0" iyz="-0.0" izz="0.0"/>
  </inertial>
  <visual>
    <origin rpy="0 0 0" xyz="-0.044566 -0.095323 -0.087187"/>
    <geometry>
      <mesh filename="package://Sunny-ROS_description/meshes/Rodamiento_684Z_v2_1.stl" scale="0.001 0.001 0.001"/>
    </geometry>
    <material name="silver"/>
  </visual>
  <collision>
    <origin rpy="0 0 0" xyz="-0.044566 -0.095323 -0.087187"/>
    <geometry>
      <mesh filename="package://Sunny-ROS_description/meshes/Rodamiento_684Z_v2_1.stl" scale="0.001 0.001 0.001"/>
    </geometry>
  </collision>
</link>

<link name="Rodamiento_684Z_v2_3">
  <inertial>
    <origin rpy="0 0 0" xyz="6.679823963406939e-08 0.001799647218284725 -4.301419296165454e-07"/>
    <mass value="0.0014793330260135641"/>
    <inertia ixx="0.0" ixy="0.0" ixz="-0.0" iyy="0.0" iyz="-0.0" izz="0.0"/>
  </inertial>
  <visual>
    <origin rpy="0 0 0" xyz="0.045434 -0.095323 -0.087187"/>
    <geometry>
      <mesh filename="package://Sunny-ROS_description/meshes/Rodamiento_684Z_v2_3.stl" scale="0.001 0.001 0.001"/>
    </geometry>
    <material name="silver"/>
  </visual>
  <collision>
    <origin rpy="0 0 0" xyz="0.045434 -0.095323 -0.087187"/>
    <geometry>
      <mesh filename="package://Sunny-ROS_description/meshes/Rodamiento_684Z_v2_3.stl" scale="0.001 0.001 0.001"/>
    </geometry>
  </collision>
</link>

<link name="piernaInferior_2_v3_1">
  <inertial>
    <origin rpy="0 0 0" xyz="0.0030774778926645208 -0.03326653812436632 -0.0324523994599899"/>
    <mass value="0.011922345304434763"/>
    <inertia ixx="2.1e-05" ixy="1e-06" ixz="1e-06" iyy="8e-06" iyz="-1e-05" izz="1.3e-05"/>
  </inertial>
  <visual>
    <origin rpy="0 0 0" xyz="-0.074816 0.015977 -0.087187"/>
    <geometry>
      <mesh filename="package://Sunny-ROS_description/meshes/piernaInferior_2_v3_1.stl" scale="0.001 0.001 0.001"/>
    </geometry>
    <material name="silver"/>
  </visual>
  <collision>
    <origin rpy="0 0 0" xyz="-0.074816 0.015977 -0.087187"/>
    <geometry>
      <mesh filename="package://Sunny-ROS_description/meshes/piernaInferior_2_v3_1.stl" scale="0.001 0.001 0.001"/>
    </geometry>
  </collision>
</link>

<link name="piernaInferior_2_v3_2">
  <inertial>
    <origin rpy="0 0 0" xyz="0.003077477892665159 -0.03326653812435548 -0.03245239945999035"/>
    <mass value="0.011922345304434763"/>
    <inertia ixx="2.1e-05" ixy="1e-06" ixz="1e-06" iyy="8e-06" iyz="-1e-05" izz="1.3e-05"/>
  </inertial>
  <visual>
    <origin rpy="0 0 0" xyz="-0.074816 -0.181323 -0.087187"/>
    <geometry>
      <mesh filename="package://Sunny-ROS_description/meshes/piernaInferior_2_v3_2.stl" scale="0.001 0.001 0.001"/>
    </geometry>
    <material name="silver"/>
  </visual>
  <collision>
    <origin rpy="0 0 0" xyz="-0.074816 -0.181323 -0.087187"/>
    <geometry>
      <mesh filename="package://Sunny-ROS_description/meshes/piernaInferior_2_v3_2.stl" scale="0.001 0.001 0.001"/>
    </geometry>
  </collision>
</link>

<link name="piernaInferior_1_v4_1">
  <inertial>
    <origin rpy="0 0 0" xyz="0.00460708215926732 0.022113111740100194 0.010725148951754825"/>
    <mass value="0.010538513185938668"/>
    <inertia ixx="1.5e-05" ixy="-0.0" ixz="-0.0" iyy="6e-06" iyz="-7e-06" izz="1e-05"/>
  </inertial>
  <visual>
    <origin rpy="0 0 0" xyz="-0.083066 -0.121552 -0.039744"/>
    <geometry>
      <mesh filename="package://Sunny-ROS_description/meshes/piernaInferior_1_v4_1.stl" scale="0.001 0.001 0.001"/>
    </geometry>
    <material name="silver"/>
  </visual>
  <collision>
    <origin rpy="0 0 0" xyz="-0.083066 -0.121552 -0.039744"/>
    <geometry>
      <mesh filename="package://Sunny-ROS_description/meshes/piernaInferior_1_v4_1.stl" scale="0.001 0.001 0.001"/>
    </geometry>
  </collision>
</link>

<link name="piernaInferior_1_v4_2">
  <inertial>
    <origin rpy="0 0 0" xyz="0.004607082159266751 0.022113111740089356 0.010725148951755206"/>
    <mass value="0.010538513185938668"/>
    <inertia ixx="1.5e-05" ixy="-0.0" ixz="-0.0" iyy="6e-06" iyz="-7e-06" izz="1e-05"/>
  </inertial>
  <visual>
    <origin rpy="0 0 0" xyz="-0.083066 0.075748 -0.039744"/>
    <geometry>
      <mesh filename="package://Sunny-ROS_description/meshes/piernaInferior_1_v4_2.stl" scale="0.001 0.001 0.001"/>
    </geometry>
    <material name="silver"/>
  </visual>
  <collision>
    <origin rpy="0 0 0" xyz="-0.083066 0.075748 -0.039744"/>
    <geometry>
      <mesh filename="package://Sunny-ROS_description/meshes/piernaInferior_1_v4_2.stl" scale="0.001 0.001 0.001"/>
    </geometry>
  </collision>
</link>

<link name="piernaInferior_3_v3_2">
  <inertial>
    <origin rpy="0 0 0" xyz="-1.0434536341918932e-07 -1.8579776424068606e-05 -0.0022511407246793794"/>
    <mass value="0.005236659475261711"/>
    <inertia ixx="0.0" ixy="-0.0" ixz="0.0" iyy="0.0" iyz="0.0" izz="0.0"/>
  </inertial>
  <visual>
    <origin rpy="0 0 0" xyz="-0.083066 0.090224 -0.01194"/>
    <geometry>
      <mesh filename="package://Sunny-ROS_description/meshes/piernaInferior_3_v3_2.stl" scale="0.001 0.001 0.001"/>
    </geometry>
    <material name="silver"/>
  </visual>
  <collision>
    <origin rpy="0 0 0" xyz="-0.083066 0.090224 -0.01194"/>
    <geometry>
      <mesh filename="package://Sunny-ROS_description/meshes/piernaInferior_3_v3_2.stl" scale="0.001 0.001 0.001"/>
    </geometry>
  </collision>
</link>

<link name="piernaInferior_3_v3_1">
  <inertial>
    <origin rpy="0 0 0" xyz="-1.0434536266978878e-07 -1.857977641318842e-05 -0.0022511407246798044"/>
    <mass value="0.005236659475261711"/>
    <inertia ixx="0.0" ixy="-0.0" ixz="0.0" iyy="0.0" iyz="0.0" izz="0.0"/>
  </inertial>
  <visual>
    <origin rpy="0 0 0" xyz="-0.083066 -0.107076 -0.01194"/>
    <geometry>
      <mesh filename="package://Sunny-ROS_description/meshes/piernaInferior_3_v3_1.stl" scale="0.001 0.001 0.001"/>
    </geometry>
    <material name="silver"/>
  </visual>
  <collision>
    <origin rpy="0 0 0" xyz="-0.083066 -0.107076 -0.01194"/>
    <geometry>
      <mesh filename="package://Sunny-ROS_description/meshes/piernaInferior_3_v3_1.stl" scale="0.001 0.001 0.001"/>
    </geometry>
  </collision>
</link>

<link name="piernaInferior_3_v3__1__2">
  <inertial>
    <origin rpy="0 0 0" xyz="-0.0030773482393877394 -0.033266607431391176 -0.03245246165579515"/>
    <mass value="0.011922326402476379"/>
    <inertia ixx="2.1e-05" ixy="-1e-06" ixz="-1e-06" iyy="8e-06" iyz="-1e-05" izz="1.3e-05"/>
  </inertial>
  <visual>
    <origin rpy="0 0 0" xyz="0.075684 0.015977 -0.087187"/>
    <geometry>
      <mesh filename="package://Sunny-ROS_description/meshes/piernaInferior_3_v3__1__2.stl" scale="0.001 0.001 0.001"/>
    </geometry>
    <material name="silver"/>
  </visual>
  <collision>
    <origin rpy="0 0 0" xyz="0.075684 0.015977 -0.087187"/>
    <geometry>
      <mesh filename="package://Sunny-ROS_description/meshes/piernaInferior_3_v3__1__2.stl" scale="0.001 0.001 0.001"/>
    </geometry>
  </collision>
</link>

<link name="piernaInferior_3_v3__1__1">
  <inertial>
    <origin rpy="0 0 0" xyz="-0.0030773482393873924 -0.03326660743138071 -0.03245246165579571"/>
    <mass value="0.011922326402476379"/>
    <inertia ixx="2.1e-05" ixy="-1e-06" ixz="-1e-06" iyy="8e-06" iyz="-1e-05" izz="1.3e-05"/>
  </inertial>
  <visual>
    <origin rpy="0 0 0" xyz="0.075684 -0.181323 -0.087187"/>
    <geometry>
      <mesh filename="package://Sunny-ROS_description/meshes/piernaInferior_3_v3__1__1.stl" scale="0.001 0.001 0.001"/>
    </geometry>
    <material name="silver"/>
  </visual>
  <collision>
    <origin rpy="0 0 0" xyz="0.075684 -0.181323 -0.087187"/>
    <geometry>
      <mesh filename="package://Sunny-ROS_description/meshes/piernaInferior_3_v3__1__1.stl" scale="0.001 0.001 0.001"/>
    </geometry>
  </collision>
</link>

<link name="piernaInferior_2_v3__1__2">
  <inertial>
    <origin rpy="0 0 0" xyz="-0.004606946901274098 0.022113119500709315 0.010725166935839366"/>
    <mass value="0.010538496684487742"/>
    <inertia ixx="1.5e-05" ixy="0.0" ixz="0.0" iyy="6e-06" iyz="-7e-06" izz="1e-05"/>
  </inertial>
  <visual>
    <origin rpy="0 0 0" xyz="0.083934 0.075748 -0.039744"/>
    <geometry>
      <mesh filename="package://Sunny-ROS_description/meshes/piernaInferior_2_v3__1__2.stl" scale="0.001 0.001 0.001"/>
    </geometry>
    <material name="silver"/>
  </visual>
  <collision>
    <origin rpy="0 0 0" xyz="0.083934 0.075748 -0.039744"/>
    <geometry>
      <mesh filename="package://Sunny-ROS_description/meshes/piernaInferior_2_v3__1__2.stl" scale="0.001 0.001 0.001"/>
    </geometry>
  </collision>
</link>

<link name="piernaInferior_2_v3__1__1">
  <inertial>
    <origin rpy="0 0 0" xyz="-0.004606946901273695 0.022113119500719813 0.010725166935838776"/>
    <mass value="0.010538496684487742"/>
    <inertia ixx="1.5e-05" ixy="0.0" ixz="0.0" iyy="6e-06" iyz="-7e-06" izz="1e-05"/>
  </inertial>
  <visual>
    <origin rpy="0 0 0" xyz="0.083934 -0.121552 -0.039744"/>
    <geometry>
      <mesh filename="package://Sunny-ROS_description/meshes/piernaInferior_2_v3__1__1.stl" scale="0.001 0.001 0.001"/>
    </geometry>
    <material name="silver"/>
  </visual>
  <collision>
    <origin rpy="0 0 0" xyz="0.083934 -0.121552 -0.039744"/>
    <geometry>
      <mesh filename="package://Sunny-ROS_description/meshes/piernaInferior_2_v3__1__1.stl" scale="0.001 0.001 0.001"/>
    </geometry>
  </collision>
</link>

<link name="piernaInferior_1_v3_1">
  <inertial>
    <origin rpy="0 0 0" xyz="-1.255145439943428e-07 1.935320521044559e-05 -0.0022511060554291362"/>
    <mass value="0.005236720980426676"/>
    <inertia ixx="0.0" ixy="0.0" ixz="0.0" iyy="0.0" iyz="-0.0" izz="0.0"/>
  </inertial>
  <visual>
    <origin rpy="0 0 0" xyz="0.083934 -0.107076 -0.01194"/>
    <geometry>
      <mesh filename="package://Sunny-ROS_description/meshes/piernaInferior_1_v3_1.stl" scale="0.001 0.001 0.001"/>
    </geometry>
    <material name="silver"/>
  </visual>
  <collision>
    <origin rpy="0 0 0" xyz="0.083934 -0.107076 -0.01194"/>
    <geometry>
      <mesh filename="package://Sunny-ROS_description/meshes/piernaInferior_1_v3_1.stl" scale="0.001 0.001 0.001"/>
    </geometry>
  </collision>
</link>

<link name="piernaInferior_1_v3_2">
  <inertial>
    <origin rpy="0 0 0" xyz="-1.2551454414699847e-07 1.9353205198913148e-05 -0.0022511060554285846"/>
    <mass value="0.005236720980426676"/>
    <inertia ixx="0.0" ixy="0.0" ixz="0.0" iyy="0.0" iyz="-0.0" izz="0.0"/>
  </inertial>
  <visual>
    <origin rpy="0 0 0" xyz="0.083934 0.090224 -0.01194"/>
    <geometry>
      <mesh filename="package://Sunny-ROS_description/meshes/piernaInferior_1_v3_2.stl" scale="0.001 0.001 0.001"/>
    </geometry>
    <material name="silver"/>
  </visual>
  <collision>
    <origin rpy="0 0 0" xyz="0.083934 0.090224 -0.01194"/>
    <geometry>
      <mesh filename="package://Sunny-ROS_description/meshes/piernaInferior_1_v3_2.stl" scale="0.001 0.001 0.001"/>
    </geometry>
  </collision>
</link>

<link name="cabeza_DEL_v9_1">
  <inertial>
    <origin rpy="0 0 0" xyz="0.017000076604881433 -0.006707832209100706 0.031861189728520194"/>
    <mass value="0.021539990229287338"/>
    <inertia ixx="8e-06" ixy="-0.0" ixz="-0.0" iyy="2.7e-05" iyz="0.0" izz="2.1e-05"/>
  </inertial>
  <visual>
    <origin rpy="0 0 0" xyz="0.017434 0.158327 -0.050687"/>
    <geometry>
      <mesh filename="package://Sunny-ROS_description/meshes/cabeza_DEL_v9_1.stl" scale="0.001 0.001 0.001"/>
    </geometry>
    <material name="silver"/>
  </visual>
  <collision>
    <origin rpy="0 0 0" xyz="0.017434 0.158327 -0.050687"/>
    <geometry>
      <mesh filename="package://Sunny-ROS_description/meshes/cabeza_DEL_v9_1.stl" scale="0.001 0.001 0.001"/>
    </geometry>
  </collision>
</link>

<link name="cabeza_TRA_v5_1">
  <inertial>
    <origin rpy="0 0 0" xyz="0.017000058302178597 0.0067420073158874355 0.031557409992354006"/>
    <mass value="0.02234556646035176"/>
    <inertia ixx="8e-06" ixy="-0.0" ixz="0.0" iyy="2.8e-05" iyz="-1e-06" izz="2.1e-05"/>
  </inertial>
  <visual>
    <origin rpy="0 0 0" xyz="0.017434 -0.103673 -0.050687"/>
    <geometry>
      <mesh filename="package://Sunny-ROS_description/meshes/cabeza_TRA_v5_1.stl" scale="0.001 0.001 0.001"/>
    </geometry>
    <material name="silver"/>
  </visual>
  <collision>
    <origin rpy="0 0 0" xyz="0.017434 -0.103673 -0.050687"/>
    <geometry>
      <mesh filename="package://Sunny-ROS_description/meshes/cabeza_TRA_v5_1.stl" scale="0.001 0.001 0.001"/>
    </geometry>
  </collision>
</link>

<link name="OLED_v1_1">
  <inertial>
    <origin rpy="0 0 0" xyz="0.01522506679816483 -0.0028986116694890846 -0.014727589748395581"/>
    <mass value="0.017692720206010867"/>
    <inertia ixx="1e-06" ixy="-0.0" ixz="0.0" iyy="3e-06" iyz="-0.0" izz="2e-06"/>
  </inertial>
  <visual>
    <origin rpy="0 0 0" xyz="0.015759 -0.116003 -0.092612"/>
    <geometry>
      <mesh filename="package://Sunny-ROS_description/meshes/OLED_v1_1.stl" scale="0.001 0.001 0.001"/>
    </geometry>
    <material name="silver"/>
  </visual>
  <collision>
    <origin rpy="0 0 0" xyz="0.015759 -0.116003 -0.092612"/>
    <geometry>
      <mesh filename="package://Sunny-ROS_description/meshes/OLED_v1_1.stl" scale="0.001 0.001 0.001"/>
    </geometry>
  </collision>
</link>

<link name="HBV_-_Camera_v3_1">
  <inertial>
    <origin rpy="0 0 0" xyz="-0.03799993325814202 -0.007701381766969939 -0.009043558365645826"/>
    <mass value="0.08018006065656721"/>
    <inertia ixx="7e-06" ixy="-0.0" ixz="0.0" iyy="6.5e-05" iyz="0.0" izz="6.9e-05"/>
  </inertial>
  <visual>
    <origin rpy="0 0 0" xyz="-0.037566 0.160327 -0.093187"/>
    <geometry>
      <mesh filename="package://Sunny-ROS_description/meshes/HBV_-_Camera_v3_1.stl" scale="0.001 0.001 0.001"/>
    </geometry>
    <material name="silver"/>
  </visual>
  <collision>
    <origin rpy="0 0 0" xyz="-0.037566 0.160327 -0.093187"/>
    <geometry>
      <mesh filename="package://Sunny-ROS_description/meshes/HBV_-_Camera_v3_1.stl" scale="0.001 0.001 0.001"/>
    </geometry>
  </collision>
</link>

<link name="centroCuerpo_SUP_1_v12_1">
  <inertial>
    <origin rpy="0 0 0" xyz="0.030250066783809332 0.0591566272502973 0.002333575229415616"/>
    <mass value="0.014182886203915107"/>
    <inertia ixx="2.6e-05" ixy="0.0" ixz="-0.0" iyy="5e-06" iyz="0.0" izz="3e-05"/>
  </inertial>
  <visual>
    <origin rpy="0 0 0" xyz="0.030684 0.162281 -0.103687"/>
    <geometry>
      <mesh filename="package://Sunny-ROS_description/meshes/centroCuerpo_SUP_1_v12_1.stl" scale="0.001 0.001 0.001"/>
    </geometry>
    <material name="silver"/>
  </visual>
  <collision>
    <origin rpy="0 0 0" xyz="0.030684 0.162281 -0.103687"/>
    <geometry>
      <mesh filename="package://Sunny-ROS_description/meshes/centroCuerpo_SUP_1_v12_1.stl" scale="0.001 0.001 0.001"/>
    </geometry>
  </collision>
</link>

<link name="centroCuerpo_SUP_2_v4_1">
  <inertial>
    <origin rpy="0 0 0" xyz="0.030000066814543896 -0.0576265205281922 0.003410148748101763"/>
    <mass value="0.02040769322828647"/>
    <inertia ixx="4e-05" ixy="-0.0" ixz="-0.0" iyy="6e-06" iyz="-2e-06" izz="4.5e-05"/>
  </inertial>
  <visual>
    <origin rpy="0 0 0" xyz="0.030684 -0.107627 -0.103687"/>
    <geometry>
      <mesh filename="package://Sunny-ROS_description/meshes/centroCuerpo_SUP_2_v4_1.stl" scale="0.001 0.001 0.001"/>
    </geometry>
    <material name="silver"/>
  </visual>
  <collision>
    <origin rpy="0 0 0" xyz="0.030684 -0.107627 -0.103687"/>
    <geometry>
      <mesh filename="package://Sunny-ROS_description/meshes/centroCuerpo_SUP_2_v4_1.stl" scale="0.001 0.001 0.001"/>
    </geometry>
  </collision>
</link>

<link name="Antena_v1_1">
  <inertial>
    <origin rpy="0 0 0" xyz="-0.004750069836300556 0.022747509798181034 0.026945485416449658"/>
    <mass value="0.04661665521588286"/>
    <inertia ixx="3.4e-05" ixy="1e-06" ixz="6e-06" iyy="3.3e-05" iyz="-4e-06" izz="4e-06"/>
  </inertial>
  <visual>
    <origin rpy="0 0 0" xyz="0.015684 -0.074394 -0.117187"/>
    <geometry>
      <mesh filename="package://Sunny-ROS_description/meshes/Antena_v1_1.stl" scale="0.001 0.001 0.001"/>
    </geometry>
    <material name="silver"/>
  </visual>
  <collision>
    <origin rpy="0 0 0" xyz="0.015684 -0.074394 -0.117187"/>
    <geometry>
      <mesh filename="package://Sunny-ROS_description/meshes/Antena_v1_1.stl" scale="0.001 0.001 0.001"/>
    </geometry>
  </collision>
</link>

<link name="Antena_v1_2">
  <inertial>
    <origin rpy="0 0 0" xyz="0.004752444566389109 0.022747509798181076 0.026945090204688563"/>
    <mass value="0.04661665521588286"/>
    <inertia ixx="3.4e-05" ixy="-1e-06" ixz="-6e-06" iyy="3.3e-05" iyz="-4e-06" izz="4e-06"/>
  </inertial>
  <visual>
    <origin rpy="0 0 0" xyz="-0.014316 -0.074394 -0.117187"/>
    <geometry>
      <mesh filename="package://Sunny-ROS_description/meshes/Antena_v1_2.stl" scale="0.001 0.001 0.001"/>
    </geometry>
    <material name="silver"/>
  </visual>
  <collision>
    <origin rpy="0 0 0" xyz="-0.014316 -0.074394 -0.117187"/>
    <geometry>
      <mesh filename="package://Sunny-ROS_description/meshes/Antena_v1_2.stl" scale="0.001 0.001 0.001"/>
    </geometry>
  </collision>
</link>

<link name="LIDAR_v3_1">
  <inertial>
    <origin rpy="0 0 0" xyz="6.679816463834145e-08 0.04935387831724013 0.033571122945797754"/>
    <mass value="0.6325892936987738"/>
    <inertia ixx="0.000422" ixy="0.0" ixz="0.0" iyy="0.000181" iyz="6.5e-05" izz="0.000485"/>
  </inertial>
  <visual>
    <origin rpy="0 0 0" xyz="0.000434 0.169863 -0.108687"/>
    <geometry>
      <mesh filename="package://Sunny-ROS_description/meshes/LIDAR_v3_1.stl" scale="0.001 0.001 0.001"/>
    </geometry>
    <material name="silver"/>
  </visual>
  <collision>
    <origin rpy="0 0 0" xyz="0.000434 0.169863 -0.108687"/>
    <geometry>
      <mesh filename="package://Sunny-ROS_description/meshes/LIDAR_v3_1.stl" scale="0.001 0.001 0.001"/>
    </geometry>
  </collision>
</link>

<link name="JT_v2_1">
  <inertial>
    <origin rpy="0 0 0" xyz="-0.043223861715892944 -0.02775214080414686 0.009088006218681749"/>
    <mass value="0.20286929639043563"/>
    <inertia ixx="0.000106" ixy="-5e-06" ixz="-1e-06" iyy="0.000124" iyz="1.2e-05" izz="0.000206"/>
  </inertial>
  <visual>
    <origin rpy="0 0 0" xyz="-0.042566 -0.001673 -0.108187"/>
    <geometry>
      <mesh filename="package://Sunny-ROS_description/meshes/JT_v2_1.stl" scale="0.001 0.001 0.001"/>
    </geometry>
    <material name="silver"/>
  </visual>
  <collision>
    <origin rpy="0 0 0" xyz="-0.042566 -0.001673 -0.108187"/>
    <geometry>
      <mesh filename="package://Sunny-ROS_description/meshes/JT_v2_1.stl" scale="0.001 0.001 0.001"/>
    </geometry>
  </collision>
</link>

<joint name="Rigid1" type="fixed">
  <origin rpy="0 0 0" xyz="0.029566 -0.077327 0.050687"/>
  <parent link="base_link"/>
  <child link="murallaCuerpo_IZQ_v12_1"/>
</joint>

<joint name="Rigid2" type="fixed">
  <origin rpy="0 0 0" xyz="-0.030434 -0.077327 0.050687"/>
  <parent link="base_link"/>
  <child link="murallaCuerpo_IZQ_1"/>
</joint>

<joint name="Rigid3" type="fixed">
  <origin rpy="0 0 0" xyz="0.0 0.1 0.0"/>
  <parent link="murallaCuerpo_IZQ_1"/>
  <child link="centroCuerpo_I_1_v9_1"/>
</joint>

<joint name="Rigid4" type="fixed">
  <origin rpy="0 0 0" xyz="0.057256 -0.03065 0.0"/>
  <parent link="centroCuerpo_I_1_v9_1"/>
  <child link="soporteElectronica_v23_1"/>
</joint>

<joint name="Rigid5" type="fixed">
  <origin rpy="0 0 0" xyz="-0.035256 0.02075 0.013"/>
  <parent link="soporteElectronica_v23_1"/>
  <child link="MPU_6050_v1_1"/>
</joint>

<joint name="Rigid6" type="fixed">
  <origin rpy="0 0 0" xyz="-0.005656 -0.00415 0.013"/>
  <parent link="soporteElectronica_v23_1"/>
  <child link="YAAJ_DCDC_StepDown_LM2596_cp_v1_2"/>
</joint>

<joint name="Rigid7" type="fixed">
  <origin rpy="0 0 0" xyz="-0.032356 -0.00405 0.013"/>
  <parent link="soporteElectronica_v23_1"/>
  <child link="YAAJ_DCDC_StepDown_LM2596_cp_v1_1"/>
</joint>

<joint name="Rigid8" type="fixed">
  <origin rpy="0 0 0" xyz="-0.027 0.05 0.02725"/>
  <parent link="murallaCuerpo_IZQ_1"/>
  <child link="Medidor_de_Bateria_2"/>
</joint>

<joint name="Rigid9" type="fixed">
  <origin rpy="0 0 0" xyz="0.027 0.05 0.027"/>
  <parent link="murallaCuerpo_IZQ_v12_1"/>
  <child link="Medidor_de_Bateria_1"/>
</joint>

<joint name="Rigid10" type="fixed">
  <origin rpy="0 0 0" xyz="-0.027 0.05 0.047"/>
  <parent link="murallaCuerpo_IZQ_1"/>
  <child link="Interruptor_v1_2"/>
</joint>

<joint name="Rigid11" type="fixed">
  <origin rpy="0 0 0" xyz="0.027 0.05 0.047"/>
  <parent link="murallaCuerpo_IZQ_v12_1"/>
  <child link="Interruptor_v1_1"/>
</joint>

<joint name="Rigid12" type="fixed">
  <origin rpy="0 0 0" xyz="0.027 0.05 0.0364"/>
  <parent link="murallaCuerpo_IZQ_v12_1"/>
  <child link="femaleThruHoleUSB_v1_2"/>
</joint>

<joint name="Rigid13" type="fixed">
  <origin rpy="0 0 0" xyz="-0.027 0.05 0.0364"/>
  <parent link="murallaCuerpo_IZQ_1"/>
  <child link="femaleThruHoleUSB_v1_1"/>
</joint>

<joint name="Rigid14" type="fixed">
  <origin rpy="0 0 0" xyz="-0.036656 0.0086 0.03"/>
  <parent link="soporteElectronica_v23_1"/>
  <child link="placa_PCA9685_v1_1"/>
</joint>

<joint name="Rigid15" type="fixed">
  <origin rpy="0 0 0" xyz="-0.02 -0.005 0.051"/>
  <parent link="murallaCuerpo_IZQ_1"/>
  <child link="motor25KG_v1_3"/>
</joint>

<joint name="Rigid16" type="fixed">
  <origin rpy="0 0 0" xyz="0.01 -0.005 0.051"/>
  <parent link="murallaCuerpo_IZQ_v12_1"/>
  <child link="motor25KG_v1_4"/>
</joint>

<joint name="Rigid17" type="fixed">
  <origin rpy="0 0 0" xyz="-0.02 0.105 0.051"/>
  <parent link="murallaCuerpo_IZQ_1"/>
  <child link="motor25KG_v1_2"/>
</joint>

<joint name="Rigid18" type="fixed">
  <origin rpy="0 0 0" xyz="0.01 0.105 0.051"/>
  <parent link="murallaCuerpo_IZQ_v12_1"/>
  <child link="motor25KG_v1_1"/>
</joint>

<joint name="HDD" type="revolute">
  <origin rpy="0 0 0" xyz="0.005 -0.01675 -0.0145"/>
  <parent link="motor25KG_v1_3"/>
  <child link="tornilloMotor_2_v1_3"/>
  <axis xyz="-0.0 -1.0 0.0"/>
  <limit effort="100" lower="-1.570796" upper="1.570796" velocity="100"/>
</joint>

<joint name="HID" type="revolute">
  <origin rpy="0 0 0" xyz="0.005 -0.01675 -0.0145"/>
  <parent link="motor25KG_v1_4"/>
  <child link="tornilloMotor_2_v1_4"/>
  <axis xyz="-0.0 -1.0 0.0"/>
  <limit effort="100" lower="-1.570796" upper="1.570796" velocity="100"/>
</joint>

<joint name="HDT" type="revolute">
  <origin rpy="0 0 0" xyz="0.005 0.01675 -0.0145"/>
  <parent link="motor25KG_v1_1"/>
  <child link="tornilloMotor_2_v1_1"/>
  <axis xyz="0.0 1.0 -0.0"/>
  <limit effort="100" lower="-1.570796" upper="1.570796" velocity="100"/>
</joint>

<joint name="HIT" type="revolute">
  <origin rpy="0 0 0" xyz="0.005 0.01675 -0.0145"/>
  <parent link="motor25KG_v1_2"/>
  <child link="tornilloMotor_2_v1_2"/>
  <axis xyz="-0.0 -1.0 0.0"/>
  <limit effort="100" lower="-1.570796" upper="1.570796" velocity="100"/>
</joint>

<joint name="Rigid23" type="fixed">
  <origin rpy="0 0 0" xyz="0.0 -0.0019 0.0"/>
  <parent link="tornilloMotor_2_v1_3"/>
  <child link="capsulaMotor_2_v3__1__1"/>
</joint>

<joint name="Rigid24" type="fixed">
  <origin rpy="0 0 0" xyz="0.0 0.0019 0.0"/>
  <parent link="tornilloMotor_2_v1_1"/>
  <child link="capsulaMotor_2_v3__1__2"/>
</joint>

<joint name="Rigid25" type="fixed">
  <origin rpy="0 0 0" xyz="0.0 -0.0019 0.0"/>
  <parent link="tornilloMotor_2_v1_4"/>
  <child link="capsulaMotor_2_v3_1"/>
</joint>

<joint name="Rigid26" type="fixed">
  <origin rpy="0 0 0" xyz="0.0 0.0019 0.0"/>
  <parent link="tornilloMotor_2_v1_2"/>
  <child link="capsulaMotor_2_v3_2"/>
</joint>

<joint name="Rigid27" type="fixed">
  <origin rpy="0 0 0" xyz="0.012 -0.0005 0.005"/>
  <parent link="capsulaMotor_2_v3_1"/>
  <child link="motor25KG_v1__1__1"/>
</joint>

<joint name="Rigid28" type="fixed">
  <origin rpy="0 0 0" xyz="0.012 -0.0005 -0.025"/>
  <parent link="capsulaMotor_2_v3_1"/>
  <child link="motor25KG_v1__1__2"/>
</joint>

<joint name="Rigid29" type="fixed">
  <origin rpy="0 0 0" xyz="0.012 0.0005 0.005"/>
  <parent link="capsulaMotor_2_v3__1__2"/>
  <child link="motor25KG_v1__1__3"/>
</joint>

<joint name="Rigid30" type="fixed">
  <origin rpy="0 0 0" xyz="0.012 0.0005 -0.015"/>
  <parent link="capsulaMotor_2_v3__1__2"/>
  <child link="motor25KG_v1__1__4"/>
</joint>

<joint name="Rigid31" type="fixed">
  <origin rpy="0 0 0" xyz="-0.012 -0.0005 0.005"/>
  <parent link="capsulaMotor_2_v3__1__1"/>
  <child link="motor25KG_v1__1__5"/>
</joint>

<joint name="Rigid32" type="fixed">
  <origin rpy="0 0 0" xyz="-0.012 -0.0005 -0.015"/>
  <parent link="capsulaMotor_2_v3__1__1"/>
  <child link="motor25KG_v1__1__6"/>
</joint>

<joint name="Rigid33" type="fixed">
  <origin rpy="0 0 0" xyz="-0.012 0.0005 -0.005"/>
  <parent link="capsulaMotor_2_v3_2"/>
  <child link="motor25KG_v1__1__7"/>
</joint>

<joint name="Rigid34" type="fixed">
  <origin rpy="0 0 0" xyz="-0.012 0.0005 -0.025"/>
  <parent link="capsulaMotor_2_v3_2"/>
  <child link="motor25KG_v1__1__8"/>
</joint>

<joint name="Rigid35" type="fixed">
  <origin rpy="0 0 0" xyz="0.0 0.049 0.01"/>
  <parent link="motor25KG_v1__1__7"/>
  <child link="capsulaMotor_1_v3_2"/>
</joint>

<joint name="Rigid36" type="fixed">
  <origin rpy="0 0 0" xyz="0.0 -0.049 0.0"/>
  <parent link="motor25KG_v1__1__5"/>
  <child link="capsulaMotor_1_v3__1__2"/>
</joint>

<joint name="Rigid37" type="fixed">
  <origin rpy="0 0 0" xyz="0.0 -0.049 0.0"/>
  <parent link="motor25KG_v1__1__1"/>
  <child link="capsulaMotor_1_v3_1"/>
</joint>

<joint name="Rigid38" type="fixed">
  <origin rpy="0 0 0" xyz="0.0 0.049 0.0"/>
  <parent link="motor25KG_v1__1__3"/>
  <child link="capsulaMotor_1_v3__1__1"/>
</joint>

<joint name="PSDD" type="revolute">
  <origin rpy="0 0 0" xyz="0.01675 -0.0145 -0.005"/>
  <parent link="motor25KG_v1__1__1"/>
  <child link="piernaSuperior_v3_2"/>
  <axis xyz="1.0 -0.0 0.0"/>
  <limit effort="100" lower="-1.570796" upper="1.570796" velocity="100"/>
</joint>

<joint name="PSDT" type="revolute">
  <origin rpy="0 0 0" xyz="0.01675 0.0345 -0.005"/>
  <parent link="motor25KG_v1__1__3"/>
  <child link="piernaSuperior_v3_1"/>
  <axis xyz="1.0 -0.0 0.0"/>
  <limit effort="100" lower="-1.570796" upper="1.570796" velocity="100"/>
</joint>

<joint name="PSID" type="revolute">
  <origin rpy="0 0 0" xyz="-0.01675 -0.0145 -0.005"/>
  <parent link="motor25KG_v1__1__5"/>
  <child link="piernaSuperior_v3_4"/>
  <axis xyz="-1.0 0.0 -0.0"/>
  <limit effort="100" lower="-1.570796" upper="1.570796" velocity="100"/>
</joint>

<joint name="PSIT" type="revolute">
  <origin rpy="0 0 0" xyz="-0.01675 0.0345 0.005"/>
  <parent link="motor25KG_v1__1__7"/>
  <child link="piernaSuperior_v3_3"/>
  <axis xyz="-1.0 0.0 -0.0"/>
  <limit effort="100" lower="-1.570796" upper="1.570796" velocity="100"/>
</joint>

<joint name="Rev43" type="continuous">
  <origin rpy="0 0 0" xyz="-0.012 0.0005 -0.005"/>
  <parent link="capsulaMotor_1_v3_1"/>
  <child link="Rodamiento_684Z_v2_4"/>
  <axis xyz="-0.0 -1.0 0.0"/>
</joint>

<joint name="Rev44" type="continuous">
  <origin rpy="0 0 0" xyz="0.012 0.0005 -0.005"/>
  <parent link="capsulaMotor_1_v3__1__2"/>
  <child link="Rodamiento_684Z_v2_2"/>
  <axis xyz="0.0 -1.0 0.0"/>
</joint>

<joint name="Rev45" type="continuous">
  <origin rpy="0 0 0" xyz="-0.012 -0.0005 -0.005"/>
  <parent link="capsulaMotor_1_v3__1__1"/>
  <child link="Rodamiento_684Z_v2_1"/>
  <axis xyz="0.0 1.0 -0.0"/>
</joint>

<joint name="Rev46" type="continuous">
  <origin rpy="0 0 0" xyz="0.012 -0.0005 -0.005"/>
  <parent link="capsulaMotor_1_v3_2"/>
  <child link="Rodamiento_684Z_v2_3"/>
  <axis xyz="0.0 -1.0 0.0"/>
</joint>

<joint name="PDID" type="revolute">
  <origin rpy="0 0 0" xyz="0.0015 0.1 0.0"/>
  <parent link="piernaSuperior_v3_2"/>
  <child link="piernaInferior_2_v3_1"/>
  <axis xyz="-1.0 0.0 -0.0"/>
  <limit effort="100" lower="-2.443461" upper="0.698132" velocity="100"/>
</joint>

<joint name="PDIT" type="revolute">
  <origin rpy="0 0 0" xyz="0.0015 0.1 0.0"/>
  <parent link="piernaSuperior_v3_1"/>
  <child link="piernaInferior_2_v3_2"/>
  <axis xyz="-1.0 0.0 -0.0"/>
  <limit effort="100" lower="-2.443461" upper="0.698132" velocity="100"/>
</joint>

<joint name="Rigid55" type="fixed">
  <origin rpy="0 0 0" xyz="0.00825 -0.059771 -0.047443"/>
  <parent link="piernaInferior_2_v3_2"/>
  <child link="piernaInferior_1_v4_1"/>
</joint>

<joint name="Rigid56" type="fixed">
  <origin rpy="0 0 0" xyz="0.00825 -0.059771 -0.047443"/>
  <parent link="piernaInferior_2_v3_1"/>
  <child link="piernaInferior_1_v4_2"/>
</joint>

<joint name="Rigid57" type="fixed">
  <origin rpy="0 0 0" xyz="0.00825 -0.074247 -0.075247"/>
  <parent link="piernaInferior_2_v3_1"/>
  <child link="piernaInferior_3_v3_2"/>
</joint>

<joint name="Rigid58" type="fixed">
  <origin rpy="0 0 0" xyz="0.0 -0.014476 -0.027804"/>
  <parent link="piernaInferior_1_v4_1"/>
  <child link="piernaInferior_3_v3_1"/>
</joint>

<joint name="PIID" type="continuous">
  <origin rpy="0 0 0" xyz="-0.0015 0.1 0.0"/>
  <parent link="piernaSuperior_v3_4"/>
  <child link="piernaInferior_3_v3__1__2"/>
  <axis xyz="1.0 0.0 0.0"/>
</joint>

<joint name="PIIT" type="continuous">
  <origin rpy="0 0 0" xyz="-0.0015 0.1 0.0"/>
  <parent link="piernaSuperior_v3_3"/>
  <child link="piernaInferior_3_v3__1__1"/>
  <axis xyz="1.0 0.0 0.0"/>
</joint>

<joint name="Rigid61" type="fixed">
  <origin rpy="0 0 0" xyz="-0.00825 -0.059771 -0.047443"/>
  <parent link="piernaInferior_3_v3__1__2"/>
  <child link="piernaInferior_2_v3__1__2"/>
</joint>

<joint name="Rigid62" type="fixed">
  <origin rpy="0 0 0" xyz="-0.00825 -0.059771 -0.047443"/>
  <parent link="piernaInferior_3_v3__1__1"/>
  <child link="piernaInferior_2_v3__1__1"/>
</joint>

<joint name="Rigid63" type="fixed">
  <origin rpy="0 0 0" xyz="0.0 -0.014476 -0.027804"/>
  <parent link="piernaInferior_2_v3__1__1"/>
  <child link="piernaInferior_1_v3_1"/>
</joint>

<joint name="Rigid64" type="fixed">
  <origin rpy="0 0 0" xyz="0.0 -0.014476 -0.027804"/>
  <parent link="piernaInferior_2_v3__1__2"/>
  <child link="piernaInferior_1_v3_2"/>
</joint>

<joint name="Rigid65" type="fixed">
  <origin rpy="0 0 0" xyz="-0.017434 -0.158327 0.050687"/>
  <parent link="base_link"/>
  <child link="cabeza_DEL_v9_1"/>
</joint>

<joint name="Rigid66" type="fixed">
  <origin rpy="0 0 0" xyz="0.013 0.081 0.0"/>
  <parent link="centroCuerpo_I_1_v9_1"/>
  <child link="cabeza_TRA_v5_1"/>
</joint>

<joint name="Rigid67" type="fixed">
  <origin rpy="0 0 0" xyz="0.001675 0.01233 0.041925"/>
  <parent link="cabeza_TRA_v5_1"/>
  <child link="OLED_v1_1"/>
</joint>

<joint name="Rigid68" type="fixed">
  <origin rpy="0 0 0" xyz="0.055 -0.002 0.0425"/>
  <parent link="cabeza_DEL_v9_1"/>
  <child link="HBV_-_Camera_v3_1"/>
</joint>

<joint name="Rigid69" type="fixed">
  <origin rpy="0 0 0" xyz="-0.01325 -0.003954 0.053"/>
  <parent link="cabeza_DEL_v9_1"/>
  <child link="centroCuerpo_SUP_1_v12_1"/>
</joint>

<joint name="Rigid70" type="fixed">
  <origin rpy="0 0 0" xyz="-0.01325 0.003954 0.053"/>
  <parent link="cabeza_TRA_v5_1"/>
  <child link="centroCuerpo_SUP_2_v4_1"/>
</joint>

<joint name="Rigid71" type="fixed">
  <origin rpy="0 0 0" xyz="0.015 -0.033233 0.0135"/>
  <parent link="centroCuerpo_SUP_2_v4_1"/>
  <child link="Antena_v1_1"/>
</joint>

<joint name="Rigid72" type="fixed">
  <origin rpy="0 0 0" xyz="0.045 -0.033233 0.0135"/>
  <parent link="centroCuerpo_SUP_2_v4_1"/>
  <child link="Antena_v1_2"/>
</joint>

<joint name="Rigid73" type="fixed">
  <origin rpy="0 0 0" xyz="0.03025 -0.007582 0.005"/>
  <parent link="centroCuerpo_SUP_1_v12_1"/>
  <child link="LIDAR_v3_1"/>
</joint>

<joint name="Rigid74" type="fixed">
  <origin rpy="0 0 0" xyz="0.013 0.079 0.0575"/>
  <parent link="murallaCuerpo_IZQ_v12_1"/>
  <child link="JT_v2_1"/>
</joint>

</robot>
